# Exception Handling in Python
Exception handling in Python allows you to gracefully handle errors and unexpected situations that may occur during the execution of a program. When an error occurs, Python raises an exception, which can be caught and processed using exception handling mechanisms. This prevents the program from abruptly terminating and allows you to take appropriate actions when errors occur. Exception handling is achieved using the try, except, else, and finally blocks. Here's how it works:

## try, except block:
1. The try block contains the code that might raise an exception.
2. If an exception occurs within the try block, the corresponding except block is executed to handle the exception.
```python
try:
    # Code that may raise an exception
    result = 10 / 0
except ZeroDivisionError:
    # Code to handle the ZeroDivisionError
    print("Error: Division by zero")
```
## Multiple except blocks:
1. You can have multiple except blocks to handle different types of exceptions.
2. The first matching except block will be executed.
```python
try:
    # Code that may raise an exception
    result = int("not_a_number")
except ValueError:
    # Code to handle the ValueError
    print("Error: Invalid input for conversion to int")
except ZeroDivisionError:
    # Code to handle the ZeroDivisionError
    print("Error: Division by zero")
```
## else block:
1. The else block is executed only if no exception occurs in the try block.
2. It is often used to perform actions when the code within the try block is successful.
```python

try:
    # Code that may raise an exception
    result = 10 / 5
except ZeroDivisionError:
    # Code to handle the ZeroDivisionError
    print("Error: Division by zero")
else:
    # Code to execute if no exception occurs
    print("Result:", result)  # Output: Result: 2.0
```

## finally block:
1. The finally block is executed regardless of whether an exception occurs or not.
2. It is commonly used to perform cleanup actions, such as closing files or releasing resources.
```python
try:
    # Code that may raise an exception
    file = open("example.txt", "r")
    # ... do something with the file ...
except IOError:
    # Code to handle the IOError
    print("Error: Unable to read the file")
finally:
    # Code to execute regardless of whether an exception occurs or not
    file.close()
```

## Raise the exception
Exception handling in Python is essential for writing robust and reliable code, ensuring that your programs handle errors gracefully and provide meaningful feedback to users in case of unexpected situations.

In Python, you can raise an exception using the raise statement. Raising an exception allows you to indicate that an error or exceptional condition has occurred in your code, and it gives you control over the flow of the program when an unexpected situation arises.

The basic syntax for raising an exception is as follows:

```python
raise ExceptionClass("Error message")
```

Here's an example of how to raise a custom exception:

```python
def divide(a, b):
    if b == 0:
        raise ValueError("Cannot divide by zero!")
    return a / b

try:
    result = divide(10, 0)
except ValueError as e:
    print("An error occurred:", e)
```

In this example, the divide function takes two arguments, a and b, and attempts to perform the division a / b. However, before performing the division, it checks if b is equal to zero. If b is zero, it raises a ValueError exception with the message "Cannot divide by zero!"

When we call divide(10, 0) inside a try-except block, the code inside the except block is executed, catching the raised exception. The program prints the error message, "An error occurred: Cannot divide by zero!"

You can also create custom exception classes by inheriting from the BaseException class or any other built-in or custom exception class.

Here's an example of a custom exception class:

```python
class MyCustomError(Exception):
    pass

def some_function():
    raise MyCustomError("This is a custom error.")

try:
    some_function()
except MyCustomError as e:
    print("Custom error caught:", e)
```

In this example, we define a custom exception class MyCustomError that inherits from the Exception class. The some_function raises this custom exception with the message "This is a custom error." The try-except block catches the custom exception and prints the error message.

Raising exceptions allows you to handle errors gracefully and provide meaningful information to users or developers about what went wrong in your code. It is a crucial feature for ensuring the robustness and reliability of your Python programs.

Custom exception handling in Python involves creating your own exception classes by inheriting from the Exception class or any other built-in exception class. This allows you to define your own exception types that suit specific scenarios in your application. Custom exceptions help improve the readability and maintainability of your code by providing meaningful error messages and context for different exceptional conditions.

Here's a step-by-step guide on how to create and use custom exceptions in Python:

Define a custom exception class:
```python
class CustomError(Exception):
    def __init__(self, message):
        self.message = message
        super().__init__(message)
```

In this example, we define a custom exception class CustomError that inherits from the built-in Exception class. We override the __init__ method to accept a custom error message, which we store in the message attribute. We also call the parent class's __init__ method to initialize the exception.

Raise the custom exception when needed:
```python
def custom_function():
    # Some condition that triggers the exception
    raise CustomError("This is a custom exception message.")
```
Handle the custom exception:
```python
try:
    custom_function()
except CustomError as e:
    print("Custom error caught:", e)
```

In this step, we try to call the custom_function, which raises the CustomError. We catch this exception using the except block and print the custom error message.

Putting it all together:

```python
class CustomError(Exception):
    def __init__(self, message):
        self.message = message
        super().__init__(message)

def custom_function():
    # Some condition that triggers the exception
    raise CustomError("This is a custom exception message.")

try:
    custom_function()
except CustomError as e:
    print("Custom error caught:", e)
```

When you run this code, it will output:

```vbnet
Custom error caught: This is a custom exception message.
```

Custom exceptions can be useful in scenarios where you need to raise specific errors for particular situations in your code. They provide a clear indication of what went wrong, allowing you or other developers to handle exceptions more effectively. Custom exceptions enhance the readability and maintainability of your code and can be an essential part of a well-designed Python application.

Let's consider an advanced example of exception handling in Python that involves reading data from a file and performing some calculations. We'll handle different types of exceptions that may occur during file handling and data processing. We'll also implement a custom exception to handle a specific scenario.

```
Suppose we have a file called "data.txt" with the following content:

10 5
20 0
30 2
40 10
```

We want to read this data, perform division, and handle exceptions appropriately.

```python

class CustomDivisionError(Exception):
    pass

def calculate_and_divide(a, b):
    if b == 0:
        raise ZeroDivisionError("Cannot divide by zero.")
    elif b % 5 == 0:
        raise CustomDivisionError("Custom division error: The denominator is a multiple of 5.")
    else:
        return a / b

try:
    with open("data.txt") as file:
        for line in file:
            numbers = line.strip().split()
            a, b = int(numbers[0]), int(numbers[1])
            try:
                result = calculate_and_divide(a, b)
                print(f"{a} / {b} = {result}")
            except ZeroDivisionError as e:
                print(f"Error: {e}")
            except CustomDivisionError as e:
                print(f"Error: {e}")
            except ValueError as e:
                print(f"Error: Invalid data format: {e}")
            except Exception as e:
                print(f"Error: {e}")
except FileNotFoundError:
    print("Error: File not found.")
except IOError:
    print("Error: An I/O error occurred.")
except Exception as e:
    print(f"Error: {e}")
```

In this example, we define a custom exception class CustomDivisionError. We also define a function calculate_and_divide that takes two numbers and performs division. Depending on the values of the numbers, different exceptions may be raised.

We use nested try-except blocks to handle exceptions appropriately. If a ZeroDivisionError is raised, we catch it and print a relevant error message. If a CustomDivisionError is raised, we handle it accordingly. If a ValueError occurs during data parsing, we catch it as well. Finally, if any other exception occurs, we catch it using a generic Exception handler.

Outside the file handling block, we catch potential FileNotFoundError and IOError that may occur during file reading.

When we run this code, the output will be:

```vbnet
2 / 1 = 2.0
Error: Cannot divide by zero.
Error: Custom division error: The denominator is a multiple of 5.
4 / 1 = 4.0
```
